Workbook
Name Slicer_SECTOR1: #N/A

Sheet Dashboard

Sheet RAW All_India_Index_Upto_April2
A1: Sector | B1: Year | C1: Month | D1: Time frame | E1: Cereals and products | F1: Meat and fish | G1: Egg | H1: Milk and products | I1: Oils and fats | J1: Fruits | K1: Vegetables | L1: Pulses and products | M1: Sugar and Confectionery | N1: Spices | O1: Non-alcoholic beverages | P1: Prepared meals, snacks, sweets etc. | Q1: Food and beverages | R1: Pan, tobacco and intoxicants | S1: Clothing | T1: Footwear | U1: Clothing and footwear | V1: Housing | W1: Fuel and light | X1: Household goods and services | Y1: Health | Z1: Transport and communication | AA1: Recreation and amusement | AB1: Education | AC1: Personal care and effects | AD1: Miscellaneous | AE1: General index
A2: Rural | B2: 2013 | C2: January | D2: =B2&" "&C2 -> 2013 January | E2: 107.5 | F2: 106.3 | G2: 108.1 | H2: 104.9 | I2: 106.1 | J2: 103.9 | K2: 101.9 | L2: 106.1 | M2: 106.8 | N2: 103.1 | O2: 104.8 | P2: 106.7 | Q2: 105.5 | R2: 105.1 | S2: 106.5 | T2: 105.8 | U2: 106.4 | V2: NA | W2: 105.5 | X2: 104.8 | Y2: 104 | Z2: 103.3 | AA2: 103.4 | AB2: 103.8 | AC2: 104.7 | AD2: 104 | AE2: 105.1
A3: Urban | B3: 2013 | C3: January | D3: =B3&" "&C3 -> 2013 January | E3: 110.5 | F3: 109.1 | G3: 113 | H3: 103.6 | I3: 103.4 | J3: 102.3 | K3: 102.9 | L3: 105.8 | M3: 105.1 | N3: 101.8 | O3: 105.1 | P3: 107.9 | Q3: 105.9 | R3: 105.2 | S3: 105.9 | T3: 105 | U3: 105.8 | V3: 100.3 | W3: 105.4 | X3: 104.8 | Y3: 104.1 | Z3: 103.2 | AA3: 102.9 | AB3: 103.5 | AC3: 104.3 | AD3: 103.7 | AE3: 104
A4: Rural+Urban | B4: 2013 | C4: January | D4: =B4&" "&C4 -> 2013 January | E4: 108.4 | F4: 107.3 | G4: 110 | H4: 104.4 | I4: 105.1 | J4: 103.2 | K4: 102.2 | L4: 106 | M4: 106.2 | N4: 102.7 | O4: 104.9 | P4: 107.3 | Q4: 105.6 | R4: 105.1 | S4: 106.3 | T4: 105.5 | U4: 106.2 | V4: 100.3 | W4: 105.5 | X4: 104.8 | Y4: 104 | Z4: 103.2 | AA4: 103.1 | AB4: 103.6 | AC4: 104.5 | AD4: 103.9 | AE4: 104.6
A5: Rural | B5: 2013 | C5: February | D5: =B5&" "&C5 -> 2013 February | E5: 109.2 | F5: 108.7 | G5: 110.2 | H5: 105.4 | I5: 106.7 | J5: 104 | K5: 102.4 | L5: 105.9 | M5: 105.7 | N5: 103.1 | O5: 105.1 | P5: 107.7 | Q5: 106.3 | R5: 105.6 | S5: 107.1 | T5: 106.3 | U5: 107 | V5: NA | W5: 106.2 | X5: 105.2 | Y5: 104.4 | Z5: 103.9 | AA5: 104 | AB5: 104.1 | AC5: 104.6 | AD5: 104.4 | AE5: 105.8
A6: Urban | B6: 2013 | C6: February | D6: =B6&" "&C6 -> 2013 February | E6: 112.9 | F6: 112.9 | G6: 116.9 | H6: 104 | I6: 103.5 | J6: 103.1 | K6: 104.9 | L6: 104.1 | M6: 103.8 | N6: 102.3 | O6: 106 | P6: 109 | Q6: 107.2 | R6: 106 | S6: 106.6 | T6: 105.5 | U6: 106.4 | V6: 100.4 | W6: 105.7 | X6: 105.2 | Y6: 104.7 | Z6: 104.4 | AA6: 103.3 | AB6: 103.7 | AC6: 104.3 | AD6: 104.3 | AE6: 104.7
A7: Rural+Urban | B7: 2013 | C7: February | D7: =B7&" "&C7 -> 2013 February | E7: 110.4 | F7: 110.2 | G7: 112.8 | H7: 104.9 | I7: 105.5 | J7: 103.6 | K7: 103.2 | L7: 105.3 | M7: 105.1 | N7: 102.8 | O7: 105.5 | P7: 108.3 | Q7: 106.6 | R7: 105.7 | S7: 106.9 | T7: 106 | U7: 106.8 | V7: 100.4 | W7: 106 | X7: 105.2 | Y7: 104.5 | Z7: 104.2 | AA7: 103.6 | AB7: 103.9 | AC7: 104.5 | AD7: 104.4 | AE7: 105.3
A8: Rural | B8: 2013 | C8: March | D8: =B8&" "&C8 -> 2013 March | E8: 110.2 | F8: 108.8 | G8: 109.9 | H8: 105.6 | I8: 106.2 | J8: 105.7 | K8: 101.4 | L8: 105.7 | M8: 105 | N8: 103.3 | O8: 105.6 | P8: 108.2 | Q8: 106.6 | R8: 106.5 | S8: 107.6 | T8: 106.8 | U8: 107.5 | V8: NA | W8: 106.1 | X8: 105.6 | Y8: 104.7 | Z8: 104.6 | AA8: 104 | AB8: 104.3 | AC8: 104.3 | AD8: 104.6 | AE8: 106
A9: Urban | B9: 2013 | C9: March | D9: =B9&" "&C9 -> 2013 March | E9: 113.9 | F9: 111.4 | G9: 113.2 | H9: 104.3 | I9: 102.7 | J9: 104.9 | K9: 103.8 | L9: 103.5 | M9: 102.6 | N9: 102.4 | O9: 107 | P9: 109.8 | Q9: 107.3 | R9: 106.8 | S9: 107.2 | T9: 106 | U9: 107 | V9: 100.4 | W9: 106 | X9: 105.7 | Y9: 105.2 | Z9: 105.5 | AA9: 103.5 | AB9: 103.8 | AC9: 104.2 | AD9: 104.9 | AE9: 105
A10: Rural+Urban | B10: 2013 | C10: March | D10: =B10&" "&C10 -> 2013 March | E10: 111.4 | F10: 109.7 | G10: 111.2 | H10: 105.1 | I10: 104.9 | J10: 105.3 | K10: 102.2 | L10: 105 | M10: 104.2 | N10: 103 | O10: 106.2 | P10: 108.9 | Q10: 106.9 | R10: 106.6 | S10: 107.4 | T10: 106.5 | U10: 107.3 | V10: 100.4 | W10: 106.1 | X10: 105.6 | Y10: 104.9 | Z10: 105.1 | AA10: 103.7 | AB10: 104 | AC10: 104.3 | AD10: 104.7 | AE10: 105.5
A11: Rural | B11: 2013 | C11: April | D11: =B11&" "&C11 -> 2013 April | E11: 110.2 | F11: 109.5 | G11: 106.9 | H11: 106.3 | I11: 105.7 | J11: 108.3 | K11: 103.4 | L11: 105.7 | M11: 104.2 | N11: 103.2 | O11: 106.5 | P11: 108.8 | Q11: 107.1 | R11: 107.1 | S11: 108.1 | T11: 107.4 | U11: 108 | V11: NA | W11: 106.5 | X11: 106.1 | Y11: 105.1 | Z11: 104.4 | AA11: 104.5 | AB11: 104.8 | AC11: 102.7 | AD11: 104.6 | AE11: 106.4
A12: Urban | B12: 2013 | C12: April | D12: =B12&" "&C12 -> 2013 April | E12: 114.6 | F12: 113.4 | G12: 106 | H12: 104.7 | I12: 102.1 | J12: 109.5 | K12: 109.7 | L12: 104.6 | M12: 102 | N12: 103.5 | O12: 108.2 | P12: 110.6 | Q12: 108.8 | R12: 108.5 | S12: 107.9 | T12: 106.4 | U12: 107.7 | V12: 100.5 | W12: 106.4 | X12: 106.5 | Y12: 105.7 | Z12: 105 | AA12: 104 | AB12: 105.2 | AC12: 103.2 | AD12: 105.1 | AE12: 105.7
A13: Rural+Urban | B13: 2013 | C13: April | D13: =B13&" "&C13 -> 2013 April | E13: 111.6 | F13: 110.9 | G13: 106.6 | H13: 105.7 | I13: 104.4 | J13: 108.9 | K13: 105.5 | L13: 105.3 | M13: 103.5 | N13: 103.3 | O13: 107.2 | P13: 109.6 | Q13: 107.7 | R13: 107.5 | S13: 108 | T13: 107 | U13: 107.9 | V13: 100.5 | W13: 106.5 | X13: 106.3 | Y13: 105.3 | Z13: 104.7 | AA13: 104.2 | AB13: 105 | AC13: 102.9 | AD13: 104.8 | AE13: 106.1
A14: Rural | B14: 2013 | C14: May | D14: =B14&" "&C14 -> 2013 May | E14: 110.9 | F14: 109.8 | G14: 105.9 | H14: 107.5 | I14: 105.3 | J14: 108.1 | K14: 107.3 | L14: 106.1 | M14: 103.7 | N14: 104 | O14: 107.4 | P14: 109.9 | Q14: 108.1 | R14: 108.1 | S14: 108.8 | T14: 107.9 | U14: 108.6 | V14: NA | W14: 107.5 | X14: 106.8 | Y14: 105.7 | Z14: 104.1 | AA14: 105 | AB14: 105.5 | AC14: 102.1 | AD14: 104.8 | AE14: 107.2
A15: Urban | B15: 2013 | C15: May | D15: =B15&" "&C15 -> 2013 May | E15: 115.4 | F15: 114.2 | G15: 102.7 | H15: 105.5 | I15: 101.5 | J15: 110.6 | K15: 123.7 | L15: 105.2 | M15: 101.9 | N15: 105 | O15: 109.1 | P15: 111.3 | Q15: 111.1 | R15: 109.8 | S15: 108.5 | T15: 106.7 | U15: 108.3 | V15: 100.5 | W15: 107.2 | X15: 107.1 | Y15: 106.2 | Z15: 103.9 | AA15: 104.6 | AB15: 105.7 | AC15: 102.6 | AD15: 104.9 | AE15: 106.6
A16: Rural+Urban | B16: 2013 | C16: May | D16: =B16&" "&C16 -> 2013 May | E16: 112.3 | F16: 111.3 | G16: 104.7 | H16: 106.8 | I16: 103.9 | J16: 109.3 | K16: 112.9 | L16: 105.8 | M16: 103.1 | N16: 104.3 | O16: 108.1 | P16: 110.5 | Q16: 109.2 | R16: 108.6 | S16: 108.7 | T16: 107.4 | U16: 108.5 | V16: 100.5 | W16: 107.4 | X16: 106.9 | Y16: 105.9 | Z16: 104 | AA16: 104.8 | AB16: 105.6 | AC16: 102.3 | AD16: 104.8 | AE16: 106.9
A17: Rural | B17: 2013 | C17: June | D17: =B17&" "&C17 -> 2013 June | E17: 112.3 | F17: 112.1 | G17: 108.1 | H17: 108.3 | I17: 105.9 | J17: 109.2 | K17: 118 | L17: 106.8 | M17: 104.1 | N17: 105.4 | O17: 108.2 | P17: 111 | Q17: 110.6 | R17: 109 | S17: 109.7 | T17: 108.8 | U17: 109.5 | V17: NA | W17: 108.5 | X17: 107.5 | Y17: 106.3 | Z17: 105 | AA17: 105.6 | AB17: 106.5 | AC17: 102.5 | AD17: 105.5 | AE17: 108.9
A18: Urban | B18: 2013 | C18: June | D18: =B18&" "&C18 -> 2013 June | E18: 117 | F18: 120.1 | G18: 112.5 | H18: 107.3 | I18: 101.3 | J18: 112.4 | K18: 143.6 | L18: 105.4 | M18: 101.4 | N18: 106.4 | O18: 110 | P18: 112.2 | Q18: 115 | R18: 110.9 | S18: 109.2 | T18: 107.2 | U18: 108.9 | V18: 106.6 | W18: 108 | X18: 107.7 | Y18: 106.5 | Z18: 105.2 | AA18: 105.2 | AB18: 108.1 | AC18: 103.3 | AD18: 106.1 | AE18: 109.7
A19: Rural+Urban | B19: 2013 | C19: June | D19: =B19&" "&C19 -> 2013 June | E19: 113.8 | F19: 114.9 | G19: 109.8 | H19: 107.9 | I19: 104.2 | J19: 110.7 | K19: 126.7 | L19: 106.3 | M19: 103.2 | N19: 105.7 | O19: 109 | P19: 111.6 | Q19: 112.2 | R19: 109.5 | S19: 109.5 | T19: 108.1 | U19: 109.3 | V19: 106.6 | W19: 108.3 | X19: 107.6 | Y19: 106.4 | Z19: 105.1 | AA19: 105.4 | AB19: 107.4 | AC19: 102.8 | AD19: 105.8 | AE19: 109.3
A20: Rural | B20: 2013 | C20: July | D20: =B20&" "&C20 -> 2013 July | E20: 113.4 | F20: 114.9 | G20: 110.5 | H20: 109.3 | I20: 106.2 | J20: 110.3 | K20: 129.2 | L20: 107.1 | M20: 104.3 | N20: 106.4 | O20: 109.1 | P20: 112.1 | Q20: 113.1 | R20: 109.8 | S20: 110.5 | T20: 109.5 | U20: 110.3 | V20: NA | W20: 109.5 | X20: 108.3 | Y20: 106.9 | Z20: 106.8 | AA20: 106.4 | AB20: 107.8 | AC20: 102.5 | AD20: 106.5 | AE20: 110.7
A21: Urban | B21: 2013 | C21: July | D21: =B21&" "&C21 -> 2013 July | E21: 117.8 | F21: 119.2 | G21: 114 | H21: 108.3 | I21: 101.1 | J21: 113.2 | K21: 160.9 | L21: 105.1 | M21: 101.3 | N21: 107.5 | O21: 110.4 | P21: 113.1 | Q21: 117.5 | R21: 111.7 | S21: 109.8 | T21: 107.8 | U21: 109.5 | V21: 107.7 | W21: 108.6 | X21: 108.1 | Y21: 107.1 | Z21: 107.3 | AA21: 105.9 | AB21: 110.1 | AC21: 103.2 | AD21: 107.3 | AE21: 111.4
A22: Rural+Urban | B22: 2013 | C22: July | D22: =B22&" "&C22 -> 2013 July | E22: 114.8 | F22: 116.4 | G22: 111.9 | H22: 108.9 | I22: 104.3 | J22: 111.7 | K22: 140 | L22: 106.4 | M22: 103.3 | N22: 106.8 | O22: 109.6 | P22: 112.6 | Q22: 114.7 | R22: 110.3 | S22: 110.2 | T22: 108.8 | U22: 110 | V22: 107.7 | W22: 109.2 | X22: 108.2 | Y22: 107 | Z22: 107.1 | AA22: 106.1 | AB22: 109.1 | AC22: 102.8 | AD22: 106.9 | AE22: 111
A23: Rural | B23: 2013 | C23: August | D23: =B23&" "&C23 -> 2013 August | E23: 114.3 | F23: 115.4 | G23: 111.1 | H23: 110 | I23: 106.4 | J23: 110.8 | K23: 138.9 | L23: 107.4 | M23: 104.1 | N23: 106.9 | O23: 109.7 | P23: 112.6 | Q23: 114.9 | R23: 110.7 | S23: 111.3 | T23: 110.2 | U23: 111.1 | V23: NA | W23: 109.9 | X23: 108.7 | Y23: 107.5 | Z23: 107.8 | AA23: 106.8 | AB23: 108.7 | AC23: 105 | AD23: 107.5 | AE23: 112.1
A24: Urban | B24: 2013 | C24: August | D24: =B24&" "&C24 -> 2013 August | E24: 118.3 | F24: 120.4 | G24: 112.7 | H24: 108.9 | I24: 101.1 | J24: 108.7 | K24: 177 | L24: 104.7 | M24: 101 | N24: 108.5 | O24: 110.9 | P24: 114.3 | Q24: 119.6 | R24: 112.4 | S24: 110.6 | T24: 108.3 | U24: 110.2 | V24: 108.9 | W24: 109.3 | X24: 108.7 | Y24: 107.6 | Z24: 108.1 | AA24: 106.5 | AB24: 110.8 | AC24: 106 | AD24: 108.3 | AE24: 112.7
A25: Rural+Urban | B25: 2013 | C25: August | D25: =B25&" "&C25 -> 2013 August | E25: 115.6 | F25: 117.2 | G25: 111.7 | H25: 109.6 | I25: 104.5 | J25: 109.8 | K25: 151.8 | L25: 106.5 | M25: 103.1 | N25: 107.4 | O25: 110.2 | P25: 113.4 | Q25: 116.6 | R25: 111.2 | S25: 111 | T25: 109.4 | U25: 110.7 | V25: 108.9 | W25: 109.7 | X25: 108.7 | Y25: 107.5 | Z25: 108 | AA25: 106.6 | AB25: 109.9 | AC25: 105.4 | AD25: 107.9 | AE25: 112.4
A26: Rural | B26: 2013 | C26: September | D26: =B26&" "&C26 -> 2013 September | E26: 115.4 | F26: 115.7 | G26: 111.7 | H26: 111 | I26: 107.4 | J26: 110.9 | K26: 154 | L26: 108.1 | M26: 104.2 | N26: 107.9 | O26: 110.4 | P26: 114 | Q26: 117.8 | R26: 111.7 | S26: 112.7 | T26: 111.4 | U26: 112.5 | V26: NA | W26: 111.1 | X26: 109.6 | Y26: 108.3 | Z26: 109.3 | AA26: 107.7 | AB26: 109.8 | AC26: 106.7 | AD26: 108.7 | AE26: 114.2
A27: Urban | B27: 2013 | C27: September | D27: =B27&" "&C27 -> 2013 September | E27: 118.6 | F27: 119.1 | G27: 113.2 | H27: 109.6 | I27: 101.7 | J27: 103.2 | K27: 174.3 | L27: 105.1 | M27: 100.8 | N27: 109.1 | O27: 111.1 | P27: 115.4 | Q27: 119.2 | R27: 112.9 | S27: 111.4 | T27: 109 | U27: 111.1 | V27: 109.7 | W27: 109.5 | X27: 109.6 | Y27: 107.9 | Z27: 110.4 | AA27: 107.4 | AB27: 111.2 | AC27: 106.9 | AD27: 109.4 | AE27: 113.2
A28: Rural+Urban | B28: 2013 | C28: September | D28: =B28&" "&C28 -> 2013 September | E28: 116.4 | F28: 116.9 | G28: 112.3 | H28: 110.5 | I28: 105.3 | J28: 107.3 | K28: 160.9 | L28: 107.1 | M28: 103.1 | N28: 108.3 | O28: 110.7 | P28: 114.6 | Q28: 118.3 | R28: 112 | S28: 112.2 | T28: 110.4 | U28: 111.9 | V28: 109.7 | W28: 110.5 | X28: 109.6 | Y28: 108.1 | Z28: 109.9 | AA28: 107.5 | AB28: 110.6 | AC28: 106.8 | AD28: 109 | AE28: 113.7
A29: Rural | B29: 2013 | C29: October | D29: =B29&" "&C29 -> 2013 October | E29: 116.3 | F29: 115.4 | G29: 112.6 | H29: 111.7 | I29: 107.7 | J29: 113.2 | K29: 164.9 | L29: 108.3 | M29: 103.9 | N29: 108.2 | O29: 111.1 | P29: 114.9 | Q29: 119.8 | R29: 112.2 | S29: 113.6 | T29: 112.3 | U29: 113.4 | V29: NA | W29: 111.6 | X29: 110.4 | Y29: 108.9 | Z29: 109.3 | AA29: 108.3 | AB29: 110.2 | AC29: 107.5 | AD29: 109.1 | AE29: 115.5
A30: Urban | B30: 2013 | C30: October | D30: =B30&" "&C30 -> 2013 October | E30: 118.9 | F30: 118.1 | G30: 114.5 | H30: 110.4 | I30: 102.3 | J30: 106.2 | K30: 183.5 | L30: 105.3 | M30: 100.2 | N30: 109.6 | O30: 111.4 | P30: 116 | Q30: 120.8 | R30: 113.5 | S30: 112.5 | T30: 109.7 | U30: 112 | V30: 110.5 | W30: 109.7 | X30: 110.2 | Y30: 108.2 | Z30: 109.7 | AA30: 108 | AB30: 111.3 | AC30: 107.3 | AD30: 109.4 | AE30: 114
A31: Rural+Urban | B31: 2013 | C31: October | D31: =B31&" "&C31 -> 2013 October | E31: 117.1 | F31: 116.3 | G31: 113.3 | H31: 111.2 | I31: 105.7 | J31: 109.9 | K31: 171.2 | L31: 107.3 | M31: 102.7 | N31: 108.7 | O31: 111.2 | P31: 115.4 | Q31: 120.2 | R31: 112.5 | S31: 113.2 | T31: 111.2 | U31: 112.8 | V31: 110.5 | W31: 110.9 | X31: 110.3 | Y31: 108.6 | Z31: 109.5 | AA31: 108.1 | AB31: 110.8 | AC31: 107.4 | AD31: 109.2 | AE31: 114.8
A32: Rural | B32: 2013 | C32: November | D32: =B32&" "&C32 -> 2013 November | E32: 117.3 | F32: 114.9 | G32: 116.2 | H32: 112.8 | I32: 108.9 | J32: 116.6 | K32: 178.1 | L32: 109.1 | M32: 103.6 | N32: 109 | O32: 111.8 | P32: 116 | Q32: 122.5 | R32: 112.8 | S32: 114.6 | T32: 113.1 | U32: 114.4 | V32: NA | W32: 112.6 | X32: 111.3 | Y32: 109.7 | Z32: 109.6 | AA32: 108.7 | AB32: 111 | AC32: 108.2 | AD32: 109.8 | AE32: 117.4
A33: Urban | B33: 2013 | C33: November | D33: =B33&" "&C33 -> 2013 November | E33: 119.8 | F33: 116.3 | G33: 122.6 | H33: 112 | I33: 103.2 | J33: 110 | K33: 192.8 | L33: 106.3 | M33: 99.5 | N33: 110.3 | O33: 111.8 | P33: 117.1 | Q33: 122.9 | R33: 114.1 | S33: 113.5 | T33: 110.3 | U33: 113 | V33: 111.1 | W33: 110 | X33: 110.9 | Y33: 108.6 | Z33: 109.5 | AA33: 108.5 | AB33: 111.3 | AC33: 107.9 | AD33: 109.6 | AE33: 115
A34: Rural+Urban | B34: 2013 | C34: November | D34: =B34&" "&C34 -> 2013 November | E34: 118.1 | F34: 115.4 | G34: 118.7 | H34: 112.5 | I34: 106.8 | J34: 113.5 | K34: 183.1 | L34: 108.2 | M34: 102.2 | N34: 109.4 | O34: 111.8 | P34: 116.5 | Q34: 122.6 | R34: 113.1 | S34: 114.2 | T34: 111.9 | U34: 113.8 | V34: 111.1 | W34: 111.6 | X34: 111.1 | Y34: 109.3 | Z34: 109.5 | AA34: 108.6 | AB34: 111.2 | AC34: 108.1 | AD34: 109.7 | AE34: 116.3
A35: Rural | B35: 2013 | C35: December | D35: =B35&" "&C35 -> 2013 December | E35: 118.4 | F35: 115.9 | G35: 120.4 | H35: 113.8 | I35: 109.5 | J35: 115.5 | K35: 145.7 | L35: 109.5 | M35: 102.9 | N35: 109.8 | O35: 112.1 | P35: 116.8 | Q35: 118.7 | R35: 113.6 | S35: 115.8 | T35: 114 | U35: 115.5 | V35: NA | W35: 112.8 | X35: 112.1 | Y35: 110.1 | Z35: 109.9 | AA35: 109.2 | AB35: 111.6 | AC35: 108.1 | AD35: 110.1 | AE35: 115.5
A36: Urban | B36: 2013 | C36: December | D36: =B36&" "&C36 -> 2013 December | E36: 120.5 | F36: 118.1 | G36: 128.5 | H36: 112.8 | I36: 103.4 | J36: 110.7 | K36: 144.8 | L36: 107.1 | M36: 98.6 | N36: 111.9 | O36: 112.1 | P36: 118.1 | Q36: 117.8 | R36: 115 | S36: 114.2 | T36: 110.9 | U36: 113.7 | V36: 110.7 | W36: 110.4 | X36: 111.3 | Y36: 109 | Z36: 109.7 | AA36: 108.9 | AB36: 111.4 | AC36: 107.7 | AD36: 109.8 | AE36: 113.3
A37: Rural+Urban | B37: 2013 | C37: December | D37: =B37&" "&C37 -> 2013 December | E37: 119.1 | F37: 116.7 | G37: 123.5 | H37: 113.4 | I37: 107.3 | J37: 113.3 | K37: 145.4 | L37: 108.7 | M37: 101.5 | N37: 110.5 | O37: 112.1 | P37: 117.4 | Q37: 118.4 | R37: 114 | S37: 115.2 | T37: 112.7 | U37: 114.8 | V37: 110.7 | W37: 111.9 | X37: 111.7 | Y37: 109.7 | Z37: 109.8 | AA37: 109 | AB37: 111.5 | AC37: 107.9 | AD37: 110 | AE37: 114.5
A38: Rural | B38: 2014 | C38: January | D38: =B38&" "&C38 -> 2014 January | E38: 118.9 | F38: 117.1 | G38: 120.5 | H38: 114.4 | I38: 109 | J38: 115.5 | K38: 123.9 | L38: 109.6 | M38: 101.8 | N38: 110.2 | O38: 112.4 | P38: 117.3 | Q38: 116 | R38: 114 | S38: 116.5 | T38: 114.5 | U38: 116.2 | V38: NA | W38: 113 | X38: 112.6 | Y38: 110.6 | Z38: 110.5 | AA38: 109.6 | AB38: 111.8 | AC38: 108.3 | AD38: 110.6 | AE38: 114.2
A39: Urban | B39: 2014 | C39: January | D39: =B39&" "&C39 -> 2014 January | E39: 121.2 | F39: 122 | G39: 129.9 | H39: 113.6 | I39: 102.9 | J39: 112.1 | K39: 118.9 | L39: 107.5 | M39: 96.9 | N39: 112.7 | O39: 112.1 | P39: 119 | Q39: 115.5 | R39: 115.7 | S39: 114.8 | T39: 111.3 | U39: 114.3 | V39: 111.6 | W39: 111 | X39: 111.9 | Y39: 109.7 | Z39: 110.8 | AA39: 109.8 | AB39: 111.5 | AC39: 108 | AD39: 110.5 | AE39: 112.9
A40: Rural+Urban | B40: 2014 | C40: January | D40: =B40&" "&C40 -> 2014 January | E40: 119.6 | F40: 118.8 | G40: 124.1 | H40: 114.1 | I40: 106.8 | J40: 113.9 | K40: 122.2 | L40: 108.9 | M40: 100.2 | N40: 111 | O40: 112.3 | P40: 118.1 | Q40: 115.8 | R40: 114.5 | S40: 115.8 | T40: 113.2 | U40: 115.4 | V40: 111.6 | W40: 112.2 | X40: 112.3 | Y40: 110.3 | Z40: 110.7 | AA40: 109.7 | AB40: 111.6 | AC40: 108.2 | AD40: 110.6 | AE40: 113.6
...

Sheet RAW DATASET COPY
A1: Sector | B1: Year | C1: Month | D1: Time frame | E1: Cereals and products | F1: Meat and fish | G1: Egg | H1: Milk and products | I1: Oils and fats | J1: Fruits | K1: Vegetables | L1: Pulses and products | M1: Sugar and Confectionery | N1: Spices | O1: Non-alcoholic beverages | P1: Prepared meals, snacks, sweets etc. | Q1: Food and beverages | R1: Pan, tobacco and intoxicants | S1: Clothing | T1: Footwear | U1: Clothing and footwear | V1: Housing | W1: Fuel and light | X1: Household goods and services | Y1: Health | Z1: Transport and communication | AA1: Recreation and amusement | AB1: Education | AC1: Personal care and effects | AD1: Miscellaneous | AE1: General index | AF1: Flag | AG1: if cpi val of fruits and veg is >150 ,then flag YES or no | AH1: COUNTYES | AI1: SPICES CPI
A2: Rural | B2: 2013 | C2: January | D2: =B2&" "&C2 -> 2013 January | E2: 107.5 | F2: 106.3 | G2: 108.1 | H2: 104.9 | I2: 106.1 | J2: 103.9 | K2: 101.9 | L2: 106.1 | M2: 106.8 | N2: 103.1 | O2: 104.8 | P2: 106.7 | Q2: 105.5 | R2: 105.1 | S2: 106.5 | T2: 105.8 | U2: 106.4 | V2: NA | W2: 105.5 | X2: 104.8 | Y2: 104 | Z2: 103.3 | AA2: 103.4 | AB2: 103.8 | AC2: 104.7 | AD2: 104 | AE2: 105.1 | AF2: =IF(AND(J2>150,K2>150),"Yes","No") -> No | AG2: AVG INFLATION val for spices cat, sector is urban and month is dec | AH2: =COUNTIF(AF2:AF373,"Yes") -> 94 | AI2: =AVERAGEIFS(N2:N374,A2:A374,"Urban",C2:C374,"December") -> 148.12 | AK2: NAME | AL2: SALARY | AM2: FLAG
A3: Urban | B3: 2013 | C3: January | D3: =B3&" "&C3 -> 2013 January | E3: 110.5 | F3: 109.1 | G3: 113 | H3: 103.6 | I3: 103.4 | J3: 102.3 | K3: 102.9 | L3: 105.8 | M3: 105.1 | N3: 101.8 | O3: 105.1 | P3: 107.9 | Q3: 105.9 | R3: 105.2 | S3: 105.9 | T3: 105 | U3: 105.8 | V3: 100.3 | W3: 105.4 | X3: 104.8 | Y3: 104.1 | Z3: 103.2 | AA3: 102.9 | AB3: 103.5 | AC3: 104.3 | AD3: 103.7 | AE3: 104 | AF3: =IF(AND(J3>150,K3>150),"Yes","No") -> No | AK3: John | AL3: 35000 | AM3: =IF(AL3<50000,CONCATENATE(AK3," ","Low"),CONCATENATE(AK3," ","High")) -> John Low
A4: Rural+Urban | B4: 2013 | C4: January | D4: =B4&" "&C4 -> 2013 January | E4: 108.4 | F4: 107.3 | G4: 110 | H4: 104.4 | I4: 105.1 | J4: 103.2 | K4: 102.2 | L4: 106 | M4: 106.2 | N4: 102.7 | O4: 104.9 | P4: 107.3 | Q4: 105.6 | R4: 105.1 | S4: 106.3 | T4: 105.5 | U4: 106.2 | V4: 100.3 | W4: 105.5 | X4: 104.8 | Y4: 104 | Z4: 103.2 | AA4: 103.1 | AB4: 103.6 | AC4: 104.5 | AD4: 103.9 | AE4: 104.6 | AF4: =IF(AND(J4>150,K4>150),"Yes","No") -> No | AK4: Sally | AL4: 55000 | AM4: =IF(AL4<50000,CONCATENATE(AK4," ","Low"),CONCATENATE(AK4," ","High")) -> Sally High
A5: Rural | B5: 2013 | C5: February | D5: =B5&" "&C5 -> 2013 February | E5: 109.2 | F5: 108.7 | G5: 110.2 | H5: 105.4 | I5: 106.7 | J5: 104 | K5: 102.4 | L5: 105.9 | M5: 105.7 | N5: 103.1 | O5: 105.1 | P5: 107.7 | Q5: 106.3 | R5: 105.6 | S5: 107.1 | T5: 106.3 | U5: 107 | V5: NA | W5: 106.2 | X5: 105.2 | Y5: 104.4 | Z5: 103.9 | AA5: 104 | AB5: 104.1 | AC5: 104.6 | AD5: 104.4 | AE5: 105.8 | AF5: =IF(AND(J5>150,K5>150),"Yes","No") -> No | AK5: Kevin | AL5: 60000 | AM5: =IF(AL5<50000,CONCATENATE(AK5," ","Low"),CONCATENATE(AK5," ","High")) -> Kevin High
A6: Urban | B6: 2013 | C6: February | D6: =B6&" "&C6 -> 2013 February | E6: 112.9 | F6: 112.9 | G6: 116.9 | H6: 104 | I6: 103.5 | J6: 103.1 | K6: 104.9 | L6: 104.1 | M6: 103.8 | N6: 102.3 | O6: 106 | P6: 109 | Q6: 107.2 | R6: 106 | S6: 106.6 | T6: 105.5 | U6: 106.4 | V6: 100.4 | W6: 105.7 | X6: 105.2 | Y6: 104.7 | Z6: 104.4 | AA6: 103.3 | AB6: 103.7 | AC6: 104.3 | AD6: 104.3 | AE6: 104.7 | AF6: =IF(AND(J6>150,K6>150),"Yes","No") -> No | AK6: Anna | AL6: 40000 | AM6: =IF(AL6<50000,CONCATENATE(AK6," ","Low"),CONCATENATE(AK6," ","High")) -> Anna Low
A7: Rural+Urban | B7: 2013 | C7: February | D7: =B7&" "&C7 -> 2013 February | E7: 110.4 | F7: 110.2 | G7: 112.8 | H7: 104.9 | I7: 105.5 | J7: 103.6 | K7: 103.2 | L7: 105.3 | M7: 105.1 | N7: 102.8 | O7: 105.5 | P7: 108.3 | Q7: 106.6 | R7: 105.7 | S7: 106.9 | T7: 106 | U7: 106.8 | V7: 100.4 | W7: 106 | X7: 105.2 | Y7: 104.5 | Z7: 104.2 | AA7: 103.6 | AB7: 103.9 | AC7: 104.5 | AD7: 104.4 | AE7: 105.3 | AF7: =IF(AND(J7>150,K7>150),"Yes","No") -> No
A8: Rural | B8: 2013 | C8: March | D8: =B8&" "&C8 -> 2013 March | E8: 110.2 | F8: 108.8 | G8: 109.9 | H8: 105.6 | I8: 106.2 | J8: 105.7 | K8: 101.4 | L8: 105.7 | M8: 105 | N8: 103.3 | O8: 105.6 | P8: 108.2 | Q8: 106.6 | R8: 106.5 | S8: 107.6 | T8: 106.8 | U8: 107.5 | V8: NA | W8: 106.1 | X8: 105.6 | Y8: 104.7 | Z8: 104.6 | AA8: 104 | AB8: 104.3 | AC8: 104.3 | AD8: 104.6 | AE8: 106 | AF8: =IF(AND(J8>150,K8>150),"Yes","No") -> No | AK8: Kevin | AL8: =INDEX(AM2:AM6,MATCH(AK8,AK2:AK6,0)) -> Kevin High
A9: Urban | B9: 2013 | C9: March | D9: =B9&" "&C9 -> 2013 March | E9: 113.9 | F9: 111.4 | G9: 113.2 | H9: 104.3 | I9: 102.7 | J9: 104.9 | K9: 103.8 | L9: 103.5 | M9: 102.6 | N9: 102.4 | O9: 107 | P9: 109.8 | Q9: 107.3 | R9: 106.8 | S9: 107.2 | T9: 106 | U9: 107 | V9: 100.4 | W9: 106 | X9: 105.7 | Y9: 105.2 | Z9: 105.5 | AA9: 103.5 | AB9: 103.8 | AC9: 104.2 | AD9: 104.9 | AE9: 105 | AF9: =IF(AND(J9>150,K9>150),"Yes","No") -> No
A10: Rural+Urban | B10: 2013 | C10: March | D10: =B10&" "&C10 -> 2013 March | E10: 111.4 | F10: 109.7 | G10: 111.2 | H10: 105.1 | I10: 104.9 | J10: 105.3 | K10: 102.2 | L10: 105 | M10: 104.2 | N10: 103 | O10: 106.2 | P10: 108.9 | Q10: 106.9 | R10: 106.6 | S10: 107.4 | T10: 106.5 | U10: 107.3 | V10: 100.4 | W10: 106.1 | X10: 105.6 | Y10: 104.9 | Z10: 105.1 | AA10: 103.7 | AB10: 104 | AC10: 104.3 | AD10: 104.7 | AE10: 105.5 | AF10: =IF(AND(J10>150,K10>150),"Yes","No") -> No
A11: Rural | B11: 2013 | C11: April | D11: =B11&" "&C11 -> 2013 April | E11: 110.2 | F11: 109.5 | G11: 106.9 | H11: 106.3 | I11: 105.7 | J11: 108.3 | K11: 103.4 | L11: 105.7 | M11: 104.2 | N11: 103.2 | O11: 106.5 | P11: 108.8 | Q11: 107.1 | R11: 107.1 | S11: 108.1 | T11: 107.4 | U11: 108 | V11: NA | W11: 106.5 | X11: 106.1 | Y11: 105.1 | Z11: 104.4 | AA11: 104.5 | AB11: 104.8 | AC11: 102.7 | AD11: 104.6 | AE11: 106.4 | AF11: =IF(AND(J11>150,K11>150),"Yes","No") -> No
A12: Urban | B12: 2013 | C12: April | D12: =B12&" "&C12 -> 2013 April | E12: 114.6 | F12: 113.4 | G12: 106 | H12: 104.7 | I12: 102.1 | J12: 109.5 | K12: 109.7 | L12: 104.6 | M12: 102 | N12: 103.5 | O12: 108.2 | P12: 110.6 | Q12: 108.8 | R12: 108.5 | S12: 107.9 | T12: 106.4 | U12: 107.7 | V12: 100.5 | W12: 106.4 | X12: 106.5 | Y12: 105.7 | Z12: 105 | AA12: 104 | AB12: 105.2 | AC12: 103.2 | AD12: 105.1 | AE12: 105.7 | AF12: =IF(AND(J12>150,K12>150),"Yes","No") -> No
A13: Rural+Urban | B13: 2013 | C13: April | D13: =B13&" "&C13 -> 2013 April | E13: 111.6 | F13: 110.9 | G13: 106.6 | H13: 105.7 | I13: 104.4 | J13: 108.9 | K13: 105.5 | L13: 105.3 | M13: 103.5 | N13: 103.3 | O13: 107.2 | P13: 109.6 | Q13: 107.7 | R13: 107.5 | S13: 108 | T13: 107 | U13: 107.9 | V13: 100.5 | W13: 106.5 | X13: 106.3 | Y13: 105.3 | Z13: 104.7 | AA13: 104.2 | AB13: 105 | AC13: 102.9 | AD13: 104.8 | AE13: 106.1 | AF13: =IF(AND(J13>150,K13>150),"Yes","No") -> No
A14: Rural | B14: 2013 | C14: May | D14: =B14&" "&C14 -> 2013 May | E14: 110.9 | F14: 109.8 | G14: 105.9 | H14: 107.5 | I14: 105.3 | J14: 108.1 | K14: 107.3 | L14: 106.1 | M14: 103.7 | N14: 104 | O14: 107.4 | P14: 109.9 | Q14: 108.1 | R14: 108.1 | S14: 108.8 | T14: 107.9 | U14: 108.6 | V14: NA | W14: 107.5 | X14: 106.8 | Y14: 105.7 | Z14: 104.1 | AA14: 105 | AB14: 105.5 | AC14: 102.1 | AD14: 104.8 | AE14: 107.2 | AF14: =IF(AND(J14>150,K14>150),"Yes","No") -> No
A15: Urban | B15: 2013 | C15: May | D15: =B15&" "&C15 -> 2013 May | E15: 115.4 | F15: 114.2 | G15: 102.7 | H15: 105.5 | I15: 101.5 | J15: 110.6 | K15: 123.7 | L15: 105.2 | M15: 101.9 | N15: 105 | O15: 109.1 | P15: 111.3 | Q15: 111.1 | R15: 109.8 | S15: 108.5 | T15: 106.7 | U15: 108.3 | V15: 100.5 | W15: 107.2 | X15: 107.1 | Y15: 106.2 | Z15: 103.9 | AA15: 104.6 | AB15: 105.7 | AC15: 102.6 | AD15: 104.9 | AE15: 106.6 | AF15: =IF(AND(J15>150,K15>150),"Yes","No") -> No
A16: Rural+Urban | B16: 2013 | C16: May | D16: =B16&" "&C16 -> 2013 May | E16: 112.3 | F16: 111.3 | G16: 104.7 | H16: 106.8 | I16: 103.9 | J16: 109.3 | K16: 112.9 | L16: 105.8 | M16: 103.1 | N16: 104.3 | O16: 108.1 | P16: 110.5 | Q16: 109.2 | R16: 108.6 | S16: 108.7 | T16: 107.4 | U16: 108.5 | V16: 100.5 | W16: 107.4 | X16: 106.9 | Y16: 105.9 | Z16: 104 | AA16: 104.8 | AB16: 105.6 | AC16: 102.3 | AD16: 104.8 | AE16: 106.9 | AF16: =IF(AND(J16>150,K16>150),"Yes","No") -> No
A17: Rural | B17: 2013 | C17: June | D17: =B17&" "&C17 -> 2013 June | E17: 112.3 | F17: 112.1 | G17: 108.1 | H17: 108.3 | I17: 105.9 | J17: 109.2 | K17: 118 | L17: 106.8 | M17: 104.1 | N17: 105.4 | O17: 108.2 | P17: 111 | Q17: 110.6 | R17: 109 | S17: 109.7 | T17: 108.8 | U17: 109.5 | V17: NA | W17: 108.5 | X17: 107.5 | Y17: 106.3 | Z17: 105 | AA17: 105.6 | AB17: 106.5 | AC17: 102.5 | AD17: 105.5 | AE17: 108.9 | AF17: =IF(AND(J17>150,K17>150),"Yes","No") -> No
A18: Urban | B18: 2013 | C18: June | D18: =B18&" "&C18 -> 2013 June | E18: 117 | F18: 120.1 | G18: 112.5 | H18: 107.3 | I18: 101.3 | J18: 112.4 | K18: 143.6 | L18: 105.4 | M18: 101.4 | N18: 106.4 | O18: 110 | P18: 112.2 | Q18: 115 | R18: 110.9 | S18: 109.2 | T18: 107.2 | U18: 108.9 | V18: 106.6 | W18: 108 | X18: 107.7 | Y18: 106.5 | Z18: 105.2 | AA18: 105.2 | AB18: 108.1 | AC18: 103.3 | AD18: 106.1 | AE18: 109.7 | AF18: =IF(AND(J18>150,K18>150),"Yes","No") -> No
A19: Rural+Urban | B19: 2013 | C19: June | D19: =B19&" "&C19 -> 2013 June | E19: 113.8 | F19: 114.9 | G19: 109.8 | H19: 107.9 | I19: 104.2 | J19: 110.7 | K19: 126.7 | L19: 106.3 | M19: 103.2 | N19: 105.7 | O19: 109 | P19: 111.6 | Q19: 112.2 | R19: 109.5 | S19: 109.5 | T19: 108.1 | U19: 109.3 | V19: 106.6 | W19: 108.3 | X19: 107.6 | Y19: 106.4 | Z19: 105.1 | AA19: 105.4 | AB19: 107.4 | AC19: 102.8 | AD19: 105.8 | AE19: 109.3 | AF19: =IF(AND(J19>150,K19>150),"Yes","No") -> No
A20: Rural | B20: 2013 | C20: July | D20: =B20&" "&C20 -> 2013 July | E20: 113.4 | F20: 114.9 | G20: 110.5 | H20: 109.3 | I20: 106.2 | J20: 110.3 | K20: 129.2 | L20: 107.1 | M20: 104.3 | N20: 106.4 | O20: 109.1 | P20: 112.1 | Q20: 113.1 | R20: 109.8 | S20: 110.5 | T20: 109.5 | U20: 110.3 | V20: NA | W20: 109.5 | X20: 108.3 | Y20: 106.9 | Z20: 106.8 | AA20: 106.4 | AB20: 107.8 | AC20: 102.5 | AD20: 106.5 | AE20: 110.7 | AF20: =IF(AND(J20>150,K20>150),"Yes","No") -> No
A21: Urban | B21: 2013 | C21: July | D21: =B21&" "&C21 -> 2013 July | E21: 117.8 | F21: 119.2 | G21: 114 | H21: 108.3 | I21: 101.1 | J21: 113.2 | K21: 160.9 | L21: 105.1 | M21: 101.3 | N21: 107.5 | O21: 110.4 | P21: 113.1 | Q21: 117.5 | R21: 111.7 | S21: 109.8 | T21: 107.8 | U21: 109.5 | V21: 107.7 | W21: 108.6 | X21: 108.1 | Y21: 107.1 | Z21: 107.3 | AA21: 105.9 | AB21: 110.1 | AC21: 103.2 | AD21: 107.3 | AE21: 111.4 | AF21: =IF(AND(J21>150,K21>150),"Yes","No") -> No
A22: Rural+Urban | B22: 2013 | C22: July | D22: =B22&" "&C22 -> 2013 July | E22: 114.8 | F22: 116.4 | G22: 111.9 | H22: 108.9 | I22: 104.3 | J22: 111.7 | K22: 140 | L22: 106.4 | M22: 103.3 | N22: 106.8 | O22: 109.6 | P22: 112.6 | Q22: 114.7 | R22: 110.3 | S22: 110.2 | T22: 108.8 | U22: 110 | V22: 107.7 | W22: 109.2 | X22: 108.2 | Y22: 107 | Z22: 107.1 | AA22: 106.1 | AB22: 109.1 | AC22: 102.8 | AD22: 106.9 | AE22: 111 | AF22: =IF(AND(J22>150,K22>150),"Yes","No") -> No
A23: Rural | B23: 2013 | C23: August | D23: =B23&" "&C23 -> 2013 August | E23: 114.3 | F23: 115.4 | G23: 111.1 | H23: 110 | I23: 106.4 | J23: 110.8 | K23: 138.9 | L23: 107.4 | M23: 104.1 | N23: 106.9 | O23: 109.7 | P23: 112.6 | Q23: 114.9 | R23: 110.7 | S23: 111.3 | T23: 110.2 | U23: 111.1 | V23: NA | W23: 109.9 | X23: 108.7 | Y23: 107.5 | Z23: 107.8 | AA23: 106.8 | AB23: 108.7 | AC23: 105 | AD23: 107.5 | AE23: 112.1 | AF23: =IF(AND(J23>150,K23>150),"Yes","No") -> No
A24: Urban | B24: 2013 | C24: August | D24: =B24&" "&C24 -> 2013 August | E24: 118.3 | F24: 120.4 | G24: 112.7 | H24: 108.9 | I24: 101.1 | J24: 108.7 | K24: 177 | L24: 104.7 | M24: 101 | N24: 108.5 | O24: 110.9 | P24: 114.3 | Q24: 119.6 | R24: 112.4 | S24: 110.6 | T24: 108.3 | U24: 110.2 | V24: 108.9 | W24: 109.3 | X24: 108.7 | Y24: 107.6 | Z24: 108.1 | AA24: 106.5 | AB24: 110.8 | AC24: 106 | AD24: 108.3 | AE24: 112.7 | AF24: =IF(AND(J24>150,K24>150),"Yes","No") -> No
A25: Rural+Urban | B25: 2013 | C25: August | D25: =B25&" "&C25 -> 2013 August | E25: 115.6 | F25: 117.2 | G25: 111.7 | H25: 109.6 | I25: 104.5 | J25: 109.8 | K25: 151.8 | L25: 106.5 | M25: 103.1 | N25: 107.4 | O25: 110.2 | P25: 113.4 | Q25: 116.6 | R25: 111.2 | S25: 111 | T25: 109.4 | U25: 110.7 | V25: 108.9 | W25: 109.7 | X25: 108.7 | Y25: 107.5 | Z25: 108 | AA25: 106.6 | AB25: 109.9 | AC25: 105.4 | AD25: 107.9 | AE25: 112.4 | AF25: =IF(AND(J25>150,K25>150),"Yes","No") -> No
A26: Rural | B26: 2013 | C26: September | D26: =B26&" "&C26 -> 2013 September | E26: 115.4 | F26: 115.7 | G26: 111.7 | H26: 111 | I26: 107.4 | J26: 110.9 | K26: 154 | L26: 108.1 | M26: 104.2 | N26: 107.9 | O26: 110.4 | P26: 114 | Q26: 117.8 | R26: 111.7 | S26: 112.7 | T26: 111.4 | U26: 112.5 | V26: NA | W26: 111.1 | X26: 109.6 | Y26: 108.3 | Z26: 109.3 | AA26: 107.7 | AB26: 109.8 | AC26: 106.7 | AD26: 108.7 | AE26: 114.2 | AF26: =IF(AND(J26>150,K26>150),"Yes","No") -> No
A27: Urban | B27: 2013 | C27: September | D27: =B27&" "&C27 -> 2013 September | E27: 118.6 | F27: 119.1 | G27: 113.2 | H27: 109.6 | I27: 101.7 | J27: 103.2 | K27: 174.3 | L27: 105.1 | M27: 100.8 | N27: 109.1 | O27: 111.1 | P27: 115.4 | Q27: 119.2 | R27: 112.9 | S27: 111.4 | T27: 109 | U27: 111.1 | V27: 109.7 | W27: 109.5 | X27: 109.6 | Y27: 107.9 | Z27: 110.4 | AA27: 107.4 | AB27: 111.2 | AC27: 106.9 | AD27: 109.4 | AE27: 113.2 | AF27: =IF(AND(J27>150,K27>150),"Yes","No") -> No
A28: Rural+Urban | B28: 2013 | C28: September | D28: =B28&" "&C28 -> 2013 September | E28: 116.4 | F28: 116.9 | G28: 112.3 | H28: 110.5 | I28: 105.3 | J28: 107.3 | K28: 160.9 | L28: 107.1 | M28: 103.1 | N28: 108.3 | O28: 110.7 | P28: 114.6 | Q28: 118.3 | R28: 112 | S28: 112.2 | T28: 110.4 | U28: 111.9 | V28: 109.7 | W28: 110.5 | X28: 109.6 | Y28: 108.1 | Z28: 109.9 | AA28: 107.5 | AB28: 110.6 | AC28: 106.8 | AD28: 109 | AE28: 113.7 | AF28: =IF(AND(J28>150,K28>150),"Yes","No") -> No
A29: Rural | B29: 2013 | C29: October | D29: =B29&" "&C29 -> 2013 October | E29: 116.3 | F29: 115.4 | G29: 112.6 | H29: 111.7 | I29: 107.7 | J29: 113.2 | K29: 164.9 | L29: 108.3 | M29: 103.9 | N29: 108.2 | O29: 111.1 | P29: 114.9 | Q29: 119.8 | R29: 112.2 | S29: 113.6 | T29: 112.3 | U29: 113.4 | V29: NA | W29: 111.6 | X29: 110.4 | Y29: 108.9 | Z29: 109.3 | AA29: 108.3 | AB29: 110.2 | AC29: 107.5 | AD29: 109.1 | AE29: 115.5 | AF29: =IF(AND(J29>150,K29>150),"Yes","No") -> No
A30: Urban | B30: 2013 | C30: October | D30: =B30&" "&C30 -> 2013 October | E30: 118.9 | F30: 118.1 | G30: 114.5 | H30: 110.4 | I30: 102.3 | J30: 106.2 | K30: 183.5 | L30: 105.3 | M30: 100.2 | N30: 109.6 | O30: 111.4 | P30: 116 | Q30: 120.8 | R30: 113.5 | S30: 112.5 | T30: 109.7 | U30: 112 | V30: 110.5 | W30: 109.7 | X30: 110.2 | Y30: 108.2 | Z30: 109.7 | AA30: 108 | AB30: 111.3 | AC30: 107.3 | AD30: 109.4 | AE30: 114 | AF30: =IF(AND(J30>150,K30>150),"Yes","No") -> No
A31: Rural+Urban | B31: 2013 | C31: October | D31: =B31&" "&C31 -> 2013 October | E31: 117.1 | F31: 116.3 | G31: 113.3 | H31: 111.2 | I31: 105.7 | J31: 109.9 | K31: 171.2 | L31: 107.3 | M31: 102.7 | N31: 108.7 | O31: 111.2 | P31: 115.4 | Q31: 120.2 | R31: 112.5 | S31: 113.2 | T31: 111.2 | U31: 112.8 | V31: 110.5 | W31: 110.9 | X31: 110.3 | Y31: 108.6 | Z31: 109.5 | AA31: 108.1 | AB31: 110.8 | AC31: 107.4 | AD31: 109.2 | AE31: 114.8 | AF31: =IF(AND(J31>150,K31>150),"Yes","No") -> No
A32: Rural | B32: 2013 | C32: November | D32: =B32&" "&C32 -> 2013 November | E32: 117.3 | F32: 114.9 | G32: 116.2 | H32: 112.8 | I32: 108.9 | J32: 116.6 | K32: 178.1 | L32: 109.1 | M32: 103.6 | N32: 109 | O32: 111.8 | P32: 116 | Q32: 122.5 | R32: 112.8 | S32: 114.6 | T32: 113.1 | U32: 114.4 | V32: NA | W32: 112.6 | X32: 111.3 | Y32: 109.7 | Z32: 109.6 | AA32: 108.7 | AB32: 111 | AC32: 108.2 | AD32: 109.8 | AE32: 117.4 | AF32: =IF(AND(J32>150,K32>150),"Yes","No") -> No
A33: Urban | B33: 2013 | C33: November | D33: =B33&" "&C33 -> 2013 November | E33: 119.8 | F33: 116.3 | G33: 122.6 | H33: 112 | I33: 103.2 | J33: 110 | K33: 192.8 | L33: 106.3 | M33: 99.5 | N33: 110.3 | O33: 111.8 | P33: 117.1 | Q33: 122.9 | R33: 114.1 | S33: 113.5 | T33: 110.3 | U33: 113 | V33: 111.1 | W33: 110 | X33: 110.9 | Y33: 108.6 | Z33: 109.5 | AA33: 108.5 | AB33: 111.3 | AC33: 107.9 | AD33: 109.6 | AE33: 115 | AF33: =IF(AND(J33>150,K33>150),"Yes","No") -> No
A34: Rural+Urban | B34: 2013 | C34: November | D34: =B34&" "&C34 -> 2013 November | E34: 118.1 | F34: 115.4 | G34: 118.7 | H34: 112.5 | I34: 106.8 | J34: 113.5 | K34: 183.1 | L34: 108.2 | M34: 102.2 | N34: 109.4 | O34: 111.8 | P34: 116.5 | Q34: 122.6 | R34: 113.1 | S34: 114.2 | T34: 111.9 | U34: 113.8 | V34: 111.1 | W34: 111.6 | X34: 111.1 | Y34: 109.3 | Z34: 109.5 | AA34: 108.6 | AB34: 111.2 | AC34: 108.1 | AD34: 109.7 | AE34: 116.3 | AF34: =IF(AND(J34>150,K34>150),"Yes","No") -> No
A35: Rural | B35: 2013 | C35: December | D35: =B35&" "&C35 -> 2013 December | E35: 118.4 | F35: 115.9 | G35: 120.4 | H35: 113.8 | I35: 109.5 | J35: 115.5 | K35: 145.7 | L35: 109.5 | M35: 102.9 | N35: 109.8 | O35: 112.1 | P35: 116.8 | Q35: 118.7 | R35: 113.6 | S35: 115.8 | T35: 114 | U35: 115.5 | V35: NA | W35: 112.8 | X35: 112.1 | Y35: 110.1 | Z35: 109.9 | AA35: 109.2 | AB35: 111.6 | AC35: 108.1 | AD35: 110.1 | AE35: 115.5 | AF35: =IF(AND(J35>150,K35>150),"Yes","No") -> No
A36: Urban | B36: 2013 | C36: December | D36: =B36&" "&C36 -> 2013 December | E36: 120.5 | F36: 118.1 | G36: 128.5 | H36: 112.8 | I36: 103.4 | J36: 110.7 | K36: 144.8 | L36: 107.1 | M36: 98.6 | N36: 111.9 | O36: 112.1 | P36: 118.1 | Q36: 117.8 | R36: 115 | S36: 114.2 | T36: 110.9 | U36: 113.7 | V36: 110.7 | W36: 110.4 | X36: 111.3 | Y36: 109 | Z36: 109.7 | AA36: 108.9 | AB36: 111.4 | AC36: 107.7 | AD36: 109.8 | AE36: 113.3 | AF36: =IF(AND(J36>150,K36>150),"Yes","No") -> No
A37: Rural+Urban | B37: 2013 | C37: December | D37: =B37&" "&C37 -> 2013 December | E37: 119.1 | F37: 116.7 | G37: 123.5 | H37: 113.4 | I37: 107.3 | J37: 113.3 | K37: 145.4 | L37: 108.7 | M37: 101.5 | N37: 110.5 | O37: 112.1 | P37: 117.4 | Q37: 118.4 | R37: 114 | S37: 115.2 | T37: 112.7 | U37: 114.8 | V37: 110.7 | W37: 111.9 | X37: 111.7 | Y37: 109.7 | Z37: 109.8 | AA37: 109 | AB37: 111.5 | AC37: 107.9 | AD37: 110 | AE37: 114.5 | AF37: =IF(AND(J37>150,K37>150),"Yes","No") -> No
A38: Rural | B38: 2014 | C38: January | D38: =B38&" "&C38 -> 2014 January | E38: 118.9 | F38: 117.1 | G38: 120.5 | H38: 114.4 | I38: 109 | J38: 115.5 | K38: 123.9 | L38: 109.6 | M38: 101.8 | N38: 110.2 | O38: 112.4 | P38: 117.3 | Q38: 116 | R38: 114 | S38: 116.5 | T38: 114.5 | U38: 116.2 | V38: NA | W38: 113 | X38: 112.6 | Y38: 110.6 | Z38: 110.5 | AA38: 109.6 | AB38: 111.8 | AC38: 108.3 | AD38: 110.6 | AE38: 114.2 | AF38: =IF(AND(J38>150,K38>150),"Yes","No") -> No
A39: Urban | B39: 2014 | C39: January | D39: =B39&" "&C39 -> 2014 January | E39: 121.2 | F39: 122 | G39: 129.9 | H39: 113.6 | I39: 102.9 | J39: 112.1 | K39: 118.9 | L39: 107.5 | M39: 96.9 | N39: 112.7 | O39: 112.1 | P39: 119 | Q39: 115.5 | R39: 115.7 | S39: 114.8 | T39: 111.3 | U39: 114.3 | V39: 111.6 | W39: 111 | X39: 111.9 | Y39: 109.7 | Z39: 110.8 | AA39: 109.8 | AB39: 111.5 | AC39: 108 | AD39: 110.5 | AE39: 112.9 | AF39: =IF(AND(J39>150,K39>150),"Yes","No") -> No
A40: Rural+Urban | B40: 2014 | C40: January | D40: =B40&" "&C40 -> 2014 January | E40: 119.6 | F40: 118.8 | G40: 124.1 | H40: 114.1 | I40: 106.8 | J40: 113.9 | K40: 122.2 | L40: 108.9 | M40: 100.2 | N40: 111 | O40: 112.3 | P40: 118.1 | Q40: 115.8 | R40: 114.5 | S40: 115.8 | T40: 113.2 | U40: 115.4 | V40: 111.6 | W40: 112.2 | X40: 112.3 | Y40: 110.3 | Z40: 110.7 | AA40: 109.7 | AB40: 111.6 | AC40: 108.2 | AD40: 110.6 | AE40: 113.6 | AF40: =IF(AND(J40>150,K40>150),"Yes","No") -> No
...

Sheet Objective
B2: Objective
B4: The objective of this case study is to analyze India’s inflation patterns using Consumer Price Index (CPI) data
B5: The CPI tracks changes in the price of a fixed basket of goods and services over time and reflects inflation trends faced by Indian consumers.
B6: This project aims to: Identify the contribution of major CPI categories toward overall inflation
B7: Examine year-over-year inflation trends
B8: Evaluate food price inflation
B9: Assess the impact of COVID-19, and Analyze how global crude oil fluctuations influence India’s inflation.

Sheet Notes
B2: Data Summary
B3: Rows | C3: 372
B4: Columns | C4: 30
B5: Sectors | C5: Rural, Urban, Rural+Urban
B6: Blank/Null Values | C6: 243
B7: Time Line | C7: 2013 - 2023
B9: Calculation for Problem Statement | C9: Formula Used
B10: BROADER CATEGORY CONTRIBUTION ANALYSIS | C10: Contribution = ( (CPI index of Category)/TOTAL CPI Value )*100
B11: YOY Increase In Overall CPI For Rural + Urban | C11: YOY Inflation = ((Current Year - Previous Year)/Previous Year) *100
B12: MONTH OVER MONTH INLFATION OVER FOOD CATEGORIES | C12: MOM Inflation = ((Current Month - Previous Month)/Previous Month) *100
B13: CATEGORY WISE INFLATION OVER COVID PERIODS | C13: Periodic Inflation = (End Of Year - Start Of Year)/Start Of Year)*100
B14: IMPACT OF CRUDE OIL WITH ALL CATEGORIES AND CORRELATION | C14: Correl Function Between Crude Oil Array and The Category Array
B16: List Of Formulas Used For Project
B17: Index Match (Nested Index Match for Multiple Criteria)
B18: Averageifs
B19: Sum
B20: Hlookup
B21: Correl
B23: Data Cleaning Steps
B24: Identification of Columns having null values using countif and sum function
B25: Replacing the null values using moving average
B27: Extras
B28: Crude Oil Data Exported from PPAC Website
B29: Data Validation for Selection of Sectors

Sheet Updated DATA SET
A1: Sector | B1: Year | C1: Month | D1: Time frame | E1: Cereals and products | F1: Meat and fish | G1: Egg | H1: Milk and products | I1: Oils and fats | J1: Fruits | K1: Vegetables | L1: Pulses and products | M1: Sugar and Confectionery | N1: Spices | O1: Non-alcoholic beverages | P1: Prepared meals, snacks, sweets etc. | Q1: Food and beverages | R1: Pan, tobacco and intoxicants | S1: Clothing | T1: Footwear | U1: Clothing and footwear | V1: Housing | W1: NEW HOUSING | X1: Fuel and light | Y1: Household goods and services | Z1: Health | AA1: Transport and communication | AB1: Recreation and amusement | AC1: Education | AD1: Personal care and effects | AE1: Miscellaneous | AF1: General index | AG1: FOOD | AH1: CLOTHING | AI1: ESSENTIAL | AJ1: HEALTH | AK1: ENERGY | AL1: LUXURY
A2: Rural | B2: 2013 | C2: January | D2: =B2&" "&C2 -> 2013 January | E2: 107.5 | F2: 106.3 | G2: 108.1 | H2: 104.9 | I2: 106.1 | J2: 103.9 | K2: 101.9 | L2: 106.1 | M2: 106.8 | N2: 103.1 | O2: 104.8 | P2: 106.7 | Q2: 105.5 | R2: 105.1 | S2: 106.5 | T2: 105.8 | U2: 106.4 | V2: NA | W2: =IF(OR(V2="NA",V2="-"),V3,V2) -> 100.3 | X2: 105.5 | Y2: 104.8 | Z2: 104 | AA2: 103.3 | AB2: 103.4 | AC2: 103.8 | AD2: 104.7 | AE2: 104 | AF2: 105.1 | AG2: =SUM($E2:$Q2) -> 1371.7 | AH2: =SUM($S2:$U2) -> 318.7 | AI2: =SUM(W2,Y2,AC2) -> 308.9 | AJ2: =SUM(Z2,AD2) -> 208.7 | AK2: =SUM(X2,AA2) -> 208.8 | AL2: =SUM(AE2,R2,AB2) -> 312.5
A3: Urban | B3: 2013 | C3: January | D3: =B3&" "&C3 -> 2013 January | E3: 110.5 | F3: 109.1 | G3: 113 | H3: 103.6 | I3: 103.4 | J3: 102.3 | K3: 102.9 | L3: 105.8 | M3: 105.1 | N3: 101.8 | O3: 105.1 | P3: 107.9 | Q3: 105.9 | R3: 105.2 | S3: 105.9 | T3: 105 | U3: 105.8 | V3: 100.3 | W3: =IF(OR(V3="NA",V3="-"),V4,V3) -> 100.3 | X3: 105.4 | Y3: 104.8 | Z3: 104.1 | AA3: 103.2 | AB3: 102.9 | AC3: 103.5 | AD3: 104.3 | AE3: 103.7 | AF3: 104 | AG3: =SUM($E3:$Q3) -> 1376.4 | AH3: =SUM($S3:$U3) -> 316.7 | AI3: =SUM(W3,Y3,AC3) -> 308.6 | AJ3: =SUM(Z3,AD3) -> 208.4 | AK3: =SUM(X3,AA3) -> 208.6 | AL3: =SUM(AE3,R3,AB3) -> 311.8
A4: Rural+Urban | B4: 2013 | C4: January | D4: =B4&" "&C4 -> 2013 January | E4: 108.4 | F4: 107.3 | G4: 110 | H4: 104.4 | I4: 105.1 | J4: 103.2 | K4: 102.2 | L4: 106 | M4: 106.2 | N4: 102.7 | O4: 104.9 | P4: 107.3 | Q4: 105.6 | R4: 105.1 | S4: 106.3 | T4: 105.5 | U4: 106.2 | V4: 100.3 | W4: =IF(OR(V4="NA",V4="-"),V5,V4) -> 100.3 | X4: 105.5 | Y4: 104.8 | Z4: 104 | AA4: 103.2 | AB4: 103.1 | AC4: 103.6 | AD4: 104.5 | AE4: 103.9 | AF4: 104.6 | AG4: =SUM($E4:$Q4) -> 1373.3 | AH4: =SUM($S4:$U4) -> 318 | AI4: =SUM(W4,Y4,AC4) -> 308.7 | AJ4: =SUM(Z4,AD4) -> 208.5 | AK4: =SUM(X4,AA4) -> 208.7 | AL4: =SUM(AE4,R4,AB4) -> 312.1
A5: Rural | B5: 2013 | C5: February | D5: =B5&" "&C5 -> 2013 February | E5: 109.2 | F5: 108.7 | G5: 110.2 | H5: 105.4 | I5: 106.7 | J5: 104 | K5: 102.4 | L5: 105.9 | M5: 105.7 | N5: 103.1 | O5: 105.1 | P5: 107.7 | Q5: 106.3 | R5: 105.6 | S5: 107.1 | T5: 106.3 | U5: 107 | V5: NA | W5: =IF(OR(V5="NA",V5="-"),V6,V5) -> 100.4 | X5: 106.2 | Y5: 105.2 | Z5: 104.4 | AA5: 103.9 | AB5: 104 | AC5: 104.1 | AD5: 104.6 | AE5: 104.4 | AF5: 105.8 | AG5: =SUM($E5:$Q5) -> 1380.4 | AH5: =SUM($S5:$U5) -> 320.4 | AI5: =SUM(W5,Y5,AC5) -> 309.7 | AJ5: =SUM(Z5,AD5) -> 209 | AK5: =SUM(X5,AA5) -> 210.1 | AL5: =SUM(AE5,R5,AB5) -> 314
A6: Urban | B6: 2013 | C6: February | D6: =B6&" "&C6 -> 2013 February | E6: 112.9 | F6: 112.9 | G6: 116.9 | H6: 104 | I6: 103.5 | J6: 103.1 | K6: 104.9 | L6: 104.1 | M6: 103.8 | N6: 102.3 | O6: 106 | P6: 109 | Q6: 107.2 | R6: 106 | S6: 106.6 | T6: 105.5 | U6: 106.4 | V6: 100.4 | W6: =IF(OR(V6="NA",V6="-"),V7,V6) -> 100.4 | X6: 105.7 | Y6: 105.2 | Z6: 104.7 | AA6: 104.4 | AB6: 103.3 | AC6: 103.7 | AD6: 104.3 | AE6: 104.3 | AF6: 104.7 | AG6: =SUM($E6:$Q6) -> 1390.6 | AH6: =SUM($S6:$U6) -> 318.5 | AI6: =SUM(W6,Y6,AC6) -> 309.3 | AJ6: =SUM(Z6,AD6) -> 209 | AK6: =SUM(X6,AA6) -> 210.1 | AL6: =SUM(AE6,R6,AB6) -> 313.6
A7: Rural+Urban | B7: 2013 | C7: February | D7: =B7&" "&C7 -> 2013 February | E7: 110.4 | F7: 110.2 | G7: 112.8 | H7: 104.9 | I7: 105.5 | J7: 103.6 | K7: 103.2 | L7: 105.3 | M7: 105.1 | N7: 102.8 | O7: 105.5 | P7: 108.3 | Q7: 106.6 | R7: 105.7 | S7: 106.9 | T7: 106 | U7: 106.8 | V7: 100.4 | W7: =IF(OR(V7="NA",V7="-"),V8,V7) -> 100.4 | X7: 106 | Y7: 105.2 | Z7: 104.5 | AA7: 104.2 | AB7: 103.6 | AC7: 103.9 | AD7: 104.5 | AE7: 104.4 | AF7: 105.3 | AG7: =SUM($E7:$Q7) -> 1384.2 | AH7: =SUM($S7:$U7) -> 319.7 | AI7: =SUM(W7,Y7,AC7) -> 309.5 | AJ7: =SUM(Z7,AD7) -> 209 | AK7: =SUM(X7,AA7) -> 210.2 | AL7: =SUM(AE7,R7,AB7) -> 313.7
A8: Rural | B8: 2013 | C8: March | D8: =B8&" "&C8 -> 2013 March | E8: 110.2 | F8: 108.8 | G8: 109.9 | H8: 105.6 | I8: 106.2 | J8: 105.7 | K8: 101.4 | L8: 105.7 | M8: 105 | N8: 103.3 | O8: 105.6 | P8: 108.2 | Q8: 106.6 | R8: 106.5 | S8: 107.6 | T8: 106.8 | U8: 107.5 | V8: NA | W8: =IF(OR(V8="NA",V8="-"),V9,V8) -> 100.4 | X8: 106.1 | Y8: 105.6 | Z8: 104.7 | AA8: 104.6 | AB8: 104 | AC8: 104.3 | AD8: 104.3 | AE8: 104.6 | AF8: 106 | AG8: =SUM($E8:$Q8) -> 1382.2 | AH8: =SUM($S8:$U8) -> 321.9 | AI8: =SUM(W8,Y8,AC8) -> 310.3 | AJ8: =SUM(Z8,AD8) -> 209 | AK8: =SUM(X8,AA8) -> 210.7 | AL8: =SUM(AE8,R8,AB8) -> 315.1
A9: Urban | B9: 2013 | C9: March | D9: =B9&" "&C9 -> 2013 March | E9: 113.9 | F9: 111.4 | G9: 113.2 | H9: 104.3 | I9: 102.7 | J9: 104.9 | K9: 103.8 | L9: 103.5 | M9: 102.6 | N9: 102.4 | O9: 107 | P9: 109.8 | Q9: 107.3 | R9: 106.8 | S9: 107.2 | T9: 106 | U9: 107 | V9: 100.4 | W9: =IF(OR(V9="NA",V9="-"),V10,V9) -> 100.4 | X9: 106 | Y9: 105.7 | Z9: 105.2 | AA9: 105.5 | AB9: 103.5 | AC9: 103.8 | AD9: 104.2 | AE9: 104.9 | AF9: 105 | AG9: =SUM($E9:$Q9) -> 1386.8 | AH9: =SUM($S9:$U9) -> 320.2 | AI9: =SUM(W9,Y9,AC9) -> 309.9 | AJ9: =SUM(Z9,AD9) -> 209.4 | AK9: =SUM(X9,AA9) -> 211.5 | AL9: =SUM(AE9,R9,AB9) -> 315.2
A10: Rural+Urban | B10: 2013 | C10: March | D10: =B10&" "&C10 -> 2013 March | E10: 111.4 | F10: 109.7 | G10: 111.2 | H10: 105.1 | I10: 104.9 | J10: 105.3 | K10: 102.2 | L10: 105 | M10: 104.2 | N10: 103 | O10: 106.2 | P10: 108.9 | Q10: 106.9 | R10: 106.6 | S10: 107.4 | T10: 106.5 | U10: 107.3 | V10: 100.4 | W10: =IF(OR(V10="NA",V10="-"),V11,V10) -> 100.4 | X10: 106.1 | Y10: 105.6 | Z10: 104.9 | AA10: 105.1 | AB10: 103.7 | AC10: 104 | AD10: 104.3 | AE10: 104.7 | AF10: 105.5 | AG10: =SUM($E10:$Q10) -> 1384 | AH10: =SUM($S10:$U10) -> 321.2 | AI10: =SUM(W10,Y10,AC10) -> 310 | AJ10: =SUM(Z10,AD10) -> 209.2 | AK10: =SUM(X10,AA10) -> 211.2 | AL10: =SUM(AE10,R10,AB10) -> 315
A11: Rural | B11: 2013 | C11: April | D11: =B11&" "&C11 -> 2013 April | E11: 110.2 | F11: 109.5 | G11: 106.9 | H11: 106.3 | I11: 105.7 | J11: 108.3 | K11: 103.4 | L11: 105.7 | M11: 104.2 | N11: 103.2 | O11: 106.5 | P11: 108.8 | Q11: 107.1 | R11: 107.1 | S11: 108.1 | T11: 107.4 | U11: 108 | V11: NA | W11: =IF(OR(V11="NA",V11="-"),V12,V11) -> 100.5 | X11: 106.5 | Y11: 106.1 | Z11: 105.1 | AA11: 104.4 | AB11: 104.5 | AC11: 104.8 | AD11: 102.7 | AE11: 104.6 | AF11: 106.4 | AG11: =SUM($E11:$Q11) -> 1385.8 | AH11: =SUM($S11:$U11) -> 323.5 | AI11: =SUM(W11,Y11,AC11) -> 311.4 | AJ11: =SUM(Z11,AD11) -> 207.8 | AK11: =SUM(X11,AA11) -> 210.9 | AL11: =SUM(AE11,R11,AB11) -> 316.2
A12: Urban | B12: 2013 | C12: April | D12: =B12&" "&C12 -> 2013 April | E12: 114.6 | F12: 113.4 | G12: 106 | H12: 104.7 | I12: 102.1 | J12: 109.5 | K12: 109.7 | L12: 104.6 | M12: 102 | N12: 103.5 | O12: 108.2 | P12: 110.6 | Q12: 108.8 | R12: 108.5 | S12: 107.9 | T12: 106.4 | U12: 107.7 | V12: 100.5 | W12: =IF(OR(V12="NA",V12="-"),V13,V12) -> 100.5 | X12: 106.4 | Y12: 106.5 | Z12: 105.7 | AA12: 105 | AB12: 104 | AC12: 105.2 | AD12: 103.2 | AE12: 105.1 | AF12: 105.7 | AG12: =SUM($E12:$Q12) -> 1397.7 | AH12: =SUM($S12:$U12) -> 322 | AI12: =SUM(W12,Y12,AC12) -> 312.2 | AJ12: =SUM(Z12,AD12) -> 208.9 | AK12: =SUM(X12,AA12) -> 211.4 | AL12: =SUM(AE12,R12,AB12) -> 317.6
A13: Rural+Urban | B13: 2013 | C13: April | D13: =B13&" "&C13 -> 2013 April | E13: 111.6 | F13: 110.9 | G13: 106.6 | H13: 105.7 | I13: 104.4 | J13: 108.9 | K13: 105.5 | L13: 105.3 | M13: 103.5 | N13: 103.3 | O13: 107.2 | P13: 109.6 | Q13: 107.7 | R13: 107.5 | S13: 108 | T13: 107 | U13: 107.9 | V13: 100.5 | W13: =IF(OR(V13="NA",V13="-"),V14,V13) -> 100.5 | X13: 106.5 | Y13: 106.3 | Z13: 105.3 | AA13: 104.7 | AB13: 104.2 | AC13: 105 | AD13: 102.9 | AE13: 104.8 | AF13: 106.1 | AG13: =SUM($E13:$Q13) -> 1390.2 | AH13: =SUM($S13:$U13) -> 322.9 | AI13: =SUM(W13,Y13,AC13) -> 311.8 | AJ13: =SUM(Z13,AD13) -> 208.2 | AK13: =SUM(X13,AA13) -> 211.2 | AL13: =SUM(AE13,R13,AB13) -> 316.5
A14: Rural | B14: 2013 | C14: May | D14: =B14&" "&C14 -> 2013 May | E14: 110.9 | F14: 109.8 | G14: 105.9 | H14: 107.5 | I14: 105.3 | J14: 108.1 | K14: 107.3 | L14: 106.1 | M14: 103.7 | N14: 104 | O14: 107.4 | P14: 109.9 | Q14: 108.1 | R14: 108.1 | S14: 108.8 | T14: 107.9 | U14: 108.6 | V14: NA | W14: =IF(OR(V14="NA",V14="-"),V15,V14) -> 100.5 | X14: 107.5 | Y14: 106.8 | Z14: 105.7 | AA14: 104.1 | AB14: 105 | AC14: 105.5 | AD14: 102.1 | AE14: 104.8 | AF14: 107.2 | AG14: =SUM($E14:$Q14) -> 1394 | AH14: =SUM($S14:$U14) -> 325.3 | AI14: =SUM(W14,Y14,AC14) -> 312.8 | AJ14: =SUM(Z14,AD14) -> 207.8 | AK14: =SUM(X14,AA14) -> 211.6 | AL14: =SUM(AE14,R14,AB14) -> 317.9
A15: Urban | B15: 2013 | C15: May | D15: =B15&" "&C15 -> 2013 May | E15: 115.4 | F15: 114.2 | G15: 102.7 | H15: 105.5 | I15: 101.5 | J15: 110.6 | K15: 123.7 | L15: 105.2 | M15: 101.9 | N15: 105 | O15: 109.1 | P15: 111.3 | Q15: 111.1 | R15: 109.8 | S15: 108.5 | T15: 106.7 | U15: 108.3 | V15: 100.5 | W15: =IF(OR(V15="NA",V15="-"),V16,V15) -> 100.5 | X15: 107.2 | Y15: 107.1 | Z15: 106.2 | AA15: 103.9 | AB15: 104.6 | AC15: 105.7 | AD15: 102.6 | AE15: 104.9 | AF15: 106.6 | AG15: =SUM($E15:$Q15) -> 1417.2 | AH15: =SUM($S15:$U15) -> 323.5 | AI15: =SUM(W15,Y15,AC15) -> 313.3 | AJ15: =SUM(Z15,AD15) -> 208.8 | AK15: =SUM(X15,AA15) -> 211.1 | AL15: =SUM(AE15,R15,AB15) -> 319.3
A16: Rural+Urban | B16: 2013 | C16: May | D16: =B16&" "&C16 -> 2013 May | E16: 112.3 | F16: 111.3 | G16: 104.7 | H16: 106.8 | I16: 103.9 | J16: 109.3 | K16: 112.9 | L16: 105.8 | M16: 103.1 | N16: 104.3 | O16: 108.1 | P16: 110.5 | Q16: 109.2 | R16: 108.6 | S16: 108.7 | T16: 107.4 | U16: 108.5 | V16: 100.5 | W16: =IF(OR(V16="NA",V16="-"),V17,V16) -> 100.5 | X16: 107.4 | Y16: 106.9 | Z16: 105.9 | AA16: 104 | AB16: 104.8 | AC16: 105.6 | AD16: 102.3 | AE16: 104.8 | AF16: 106.9 | AG16: =SUM($E16:$Q16) -> 1402.2 | AH16: =SUM($S16:$U16) -> 324.6 | AI16: =SUM(W16,Y16,AC16) -> 313 | AJ16: =SUM(Z16,AD16) -> 208.2 | AK16: =SUM(X16,AA16) -> 211.4 | AL16: =SUM(AE16,R16,AB16) -> 318.2
A17: Rural | B17: 2013 | C17: June | D17: =B17&" "&C17 -> 2013 June | E17: 112.3 | F17: 112.1 | G17: 108.1 | H17: 108.3 | I17: 105.9 | J17: 109.2 | K17: 118 | L17: 106.8 | M17: 104.1 | N17: 105.4 | O17: 108.2 | P17: 111 | Q17: 110.6 | R17: 109 | S17: 109.7 | T17: 108.8 | U17: 109.5 | V17: NA | W17: =IF(OR(V17="NA",V17="-"),V18,V17) -> 106.6 | X17: 108.5 | Y17: 107.5 | Z17: 106.3 | AA17: 105 | AB17: 105.6 | AC17: 106.5 | AD17: 102.5 | AE17: 105.5 | AF17: 108.9 | AG17: =SUM($E17:$Q17) -> 1420 | AH17: =SUM($S17:$U17) -> 328 | AI17: =SUM(W17,Y17,AC17) -> 320.6 | AJ17: =SUM(Z17,AD17) -> 208.8 | AK17: =SUM(X17,AA17) -> 213.5 | AL17: =SUM(AE17,R17,AB17) -> 320.1
A18: Urban | B18: 2013 | C18: June | D18: =B18&" "&C18 -> 2013 June | E18: 117 | F18: 120.1 | G18: 112.5 | H18: 107.3 | I18: 101.3 | J18: 112.4 | K18: 143.6 | L18: 105.4 | M18: 101.4 | N18: 106.4 | O18: 110 | P18: 112.2 | Q18: 115 | R18: 110.9 | S18: 109.2 | T18: 107.2 | U18: 108.9 | V18: 106.6 | W18: =IF(OR(V18="NA",V18="-"),V19,V18) -> 106.6 | X18: 108 | Y18: 107.7 | Z18: 106.5 | AA18: 105.2 | AB18: 105.2 | AC18: 108.1 | AD18: 103.3 | AE18: 106.1 | AF18: 109.7 | AG18: =SUM($E18:$Q18) -> 1464.6 | AH18: =SUM($S18:$U18) -> 325.3 | AI18: =SUM(W18,Y18,AC18) -> 322.4 | AJ18: =SUM(Z18,AD18) -> 209.8 | AK18: =SUM(X18,AA18) -> 213.2 | AL18: =SUM(AE18,R18,AB18) -> 322.2
A19: Rural+Urban | B19: 2013 | C19: June | D19: =B19&" "&C19 -> 2013 June | E19: 113.8 | F19: 114.9 | G19: 109.8 | H19: 107.9 | I19: 104.2 | J19: 110.7 | K19: 126.7 | L19: 106.3 | M19: 103.2 | N19: 105.7 | O19: 109 | P19: 111.6 | Q19: 112.2 | R19: 109.5 | S19: 109.5 | T19: 108.1 | U19: 109.3 | V19: 106.6 | W19: =IF(OR(V19="NA",V19="-"),V20,V19) -> 106.6 | X19: 108.3 | Y19: 107.6 | Z19: 106.4 | AA19: 105.1 | AB19: 105.4 | AC19: 107.4 | AD19: 102.8 | AE19: 105.8 | AF19: 109.3 | AG19: =SUM($E19:$Q19) -> 1436 | AH19: =SUM($S19:$U19) -> 326.9 | AI19: =SUM(W19,Y19,AC19) -> 321.6 | AJ19: =SUM(Z19,AD19) -> 209.2 | AK19: =SUM(X19,AA19) -> 213.4 | AL19: =SUM(AE19,R19,AB19) -> 320.7
A20: Rural | B20: 2013 | C20: July | D20: =B20&" "&C20 -> 2013 July | E20: 113.4 | F20: 114.9 | G20: 110.5 | H20: 109.3 | I20: 106.2 | J20: 110.3 | K20: 129.2 | L20: 107.1 | M20: 104.3 | N20: 106.4 | O20: 109.1 | P20: 112.1 | Q20: 113.1 | R20: 109.8 | S20: 110.5 | T20: 109.5 | U20: 110.3 | V20: NA | W20: =IF(OR(V20="NA",V20="-"),V21,V20) -> 107.7 | X20: 109.5 | Y20: 108.3 | Z20: 106.9 | AA20: 106.8 | AB20: 106.4 | AC20: 107.8 | AD20: 102.5 | AE20: 106.5 | AF20: 110.7 | AG20: =SUM($E20:$Q20) -> 1445.9 | AH20: =SUM($S20:$U20) -> 330.3 | AI20: =SUM(W20,Y20,AC20) -> 323.8 | AJ20: =SUM(Z20,AD20) -> 209.4 | AK20: =SUM(X20,AA20) -> 216.3 | AL20: =SUM(AE20,R20,AB20) -> 322.7
A21: Urban | B21: 2013 | C21: July | D21: =B21&" "&C21 -> 2013 July | E21: 117.8 | F21: 119.2 | G21: 114 | H21: 108.3 | I21: 101.1 | J21: 113.2 | K21: 160.9 | L21: 105.1 | M21: 101.3 | N21: 107.5 | O21: 110.4 | P21: 113.1 | Q21: 117.5 | R21: 111.7 | S21: 109.8 | T21: 107.8 | U21: 109.5 | V21: 107.7 | W21: =IF(OR(V21="NA",V21="-"),V22,V21) -> 107.7 | X21: 108.6 | Y21: 108.1 | Z21: 107.1 | AA21: 107.3 | AB21: 105.9 | AC21: 110.1 | AD21: 103.2 | AE21: 107.3 | AF21: 111.4 | AG21: =SUM($E21:$Q21) -> 1489.4 | AH21: =SUM($S21:$U21) -> 327.1 | AI21: =SUM(W21,Y21,AC21) -> 325.9 | AJ21: =SUM(Z21,AD21) -> 210.3 | AK21: =SUM(X21,AA21) -> 215.9 | AL21: =SUM(AE21,R21,AB21) -> 324.9
A22: Rural+Urban | B22: 2013 | C22: July | D22: =B22&" "&C22 -> 2013 July | E22: 114.8 | F22: 116.4 | G22: 111.9 | H22: 108.9 | I22: 104.3 | J22: 111.7 | K22: 140 | L22: 106.4 | M22: 103.3 | N22: 106.8 | O22: 109.6 | P22: 112.6 | Q22: 114.7 | R22: 110.3 | S22: 110.2 | T22: 108.8 | U22: 110 | V22: 107.7 | W22: =IF(OR(V22="NA",V22="-"),V23,V22) -> 107.7 | X22: 109.2 | Y22: 108.2 | Z22: 107 | AA22: 107.1 | AB22: 106.1 | AC22: 109.1 | AD22: 102.8 | AE22: 106.9 | AF22: 111 | AG22: =SUM($E22:$Q22) -> 1461.4 | AH22: =SUM($S22:$U22) -> 329 | AI22: =SUM(W22,Y22,AC22) -> 325 | AJ22: =SUM(Z22,AD22) -> 209.8 | AK22: =SUM(X22,AA22) -> 216.3 | AL22: =SUM(AE22,R22,AB22) -> 323.3
A23: Rural | B23: 2013 | C23: August | D23: =B23&" "&C23 -> 2013 August | E23: 114.3 | F23: 115.4 | G23: 111.1 | H23: 110 | I23: 106.4 | J23: 110.8 | K23: 138.9 | L23: 107.4 | M23: 104.1 | N23: 106.9 | O23: 109.7 | P23: 112.6 | Q23: 114.9 | R23: 110.7 | S23: 111.3 | T23: 110.2 | U23: 111.1 | V23: NA | W23: =IF(OR(V23="NA",V23="-"),V24,V23) -> 108.9 | X23: 109.9 | Y23: 108.7 | Z23: 107.5 | AA23: 107.8 | AB23: 106.8 | AC23: 108.7 | AD23: 105 | AE23: 107.5 | AF23: 112.1 | AG23: =SUM($E23:$Q23) -> 1462.5 | AH23: =SUM($S23:$U23) -> 332.6 | AI23: =SUM(W23,Y23,AC23) -> 326.3 | AJ23: =SUM(Z23,AD23) -> 212.5 | AK23: =SUM(X23,AA23) -> 217.7 | AL23: =SUM(AE23,R23,AB23) -> 325
A24: Urban | B24: 2013 | C24: August | D24: =B24&" "&C24 -> 2013 August | E24: 118.3 | F24: 120.4 | G24: 112.7 | H24: 108.9 | I24: 101.1 | J24: 108.7 | K24: 177 | L24: 104.7 | M24: 101 | N24: 108.5 | O24: 110.9 | P24: 114.3 | Q24: 119.6 | R24: 112.4 | S24: 110.6 | T24: 108.3 | U24: 110.2 | V24: 108.9 | W24: =IF(OR(V24="NA",V24="-"),V25,V24) -> 108.9 | X24: 109.3 | Y24: 108.7 | Z24: 107.6 | AA24: 108.1 | AB24: 106.5 | AC24: 110.8 | AD24: 106 | AE24: 108.3 | AF24: 112.7 | AG24: =SUM($E24:$Q24) -> 1506.1 | AH24: =SUM($S24:$U24) -> 329.1 | AI24: =SUM(W24,Y24,AC24) -> 328.4 | AJ24: =SUM(Z24,AD24) -> 213.6 | AK24: =SUM(X24,AA24) -> 217.4 | AL24: =SUM(AE24,R24,AB24) -> 327.2
A25: Rural+Urban | B25: 2013 | C25: August | D25: =B25&" "&C25 -> 2013 August | E25: 115.6 | F25: 117.2 | G25: 111.7 | H25: 109.6 | I25: 104.5 | J25: 109.8 | K25: 151.8 | L25: 106.5 | M25: 103.1 | N25: 107.4 | O25: 110.2 | P25: 113.4 | Q25: 116.6 | R25: 111.2 | S25: 111 | T25: 109.4 | U25: 110.7 | V25: 108.9 | W25: =IF(OR(V25="NA",V25="-"),V26,V25) -> 108.9 | X25: 109.7 | Y25: 108.7 | Z25: 107.5 | AA25: 108 | AB25: 106.6 | AC25: 109.9 | AD25: 105.4 | AE25: 107.9 | AF25: 112.4 | AG25: =SUM($E25:$Q25) -> 1477.4 | AH25: =SUM($S25:$U25) -> 331.1 | AI25: =SUM(W25,Y25,AC25) -> 327.5 | AJ25: =SUM(Z25,AD25) -> 212.9 | AK25: =SUM(X25,AA25) -> 217.7 | AL25: =SUM(AE25,R25,AB25) -> 325.7
A26: Rural | B26: 2013 | C26: September | D26: =B26&" "&C26 -> 2013 September | E26: 115.4 | F26: 115.7 | G26: 111.7 | H26: 111 | I26: 107.4 | J26: 110.9 | K26: 154 | L26: 108.1 | M26: 104.2 | N26: 107.9 | O26: 110.4 | P26: 114 | Q26: 117.8 | R26: 111.7 | S26: 112.7 | T26: 111.4 | U26: 112.5 | V26: NA | W26: =IF(OR(V26="NA",V26="-"),V27,V26) -> 109.7 | X26: 111.1 | Y26: 109.6 | Z26: 108.3 | AA26: 109.3 | AB26: 107.7 | AC26: 109.8 | AD26: 106.7 | AE26: 108.7 | AF26: 114.2 | AG26: =SUM($E26:$Q26) -> 1488.5 | AH26: =SUM($S26:$U26) -> 336.6 | AI26: =SUM(W26,Y26,AC26) -> 329.1 | AJ26: =SUM(Z26,AD26) -> 215 | AK26: =SUM(X26,AA26) -> 220.4 | AL26: =SUM(AE26,R26,AB26) -> 328.1
A27: Urban | B27: 2013 | C27: September | D27: =B27&" "&C27 -> 2013 September | E27: 118.6 | F27: 119.1 | G27: 113.2 | H27: 109.6 | I27: 101.7 | J27: 103.2 | K27: 174.3 | L27: 105.1 | M27: 100.8 | N27: 109.1 | O27: 111.1 | P27: 115.4 | Q27: 119.2 | R27: 112.9 | S27: 111.4 | T27: 109 | U27: 111.1 | V27: 109.7 | W27: =IF(OR(V27="NA",V27="-"),V28,V27) -> 109.7 | X27: 109.5 | Y27: 109.6 | Z27: 107.9 | AA27: 110.4 | AB27: 107.4 | AC27: 111.2 | AD27: 106.9 | AE27: 109.4 | AF27: 113.2 | AG27: =SUM($E27:$Q27) -> 1500.4 | AH27: =SUM($S27:$U27) -> 331.5 | AI27: =SUM(W27,Y27,AC27) -> 330.5 | AJ27: =SUM(Z27,AD27) -> 214.8 | AK27: =SUM(X27,AA27) -> 219.9 | AL27: =SUM(AE27,R27,AB27) -> 329.7
A28: Rural+Urban | B28: 2013 | C28: September | D28: =B28&" "&C28 -> 2013 September | E28: 116.4 | F28: 116.9 | G28: 112.3 | H28: 110.5 | I28: 105.3 | J28: 107.3 | K28: 160.9 | L28: 107.1 | M28: 103.1 | N28: 108.3 | O28: 110.7 | P28: 114.6 | Q28: 118.3 | R28: 112 | S28: 112.2 | T28: 110.4 | U28: 111.9 | V28: 109.7 | W28: =IF(OR(V28="NA",V28="-"),V29,V28) -> 109.7 | X28: 110.5 | Y28: 109.6 | Z28: 108.1 | AA28: 109.9 | AB28: 107.5 | AC28: 110.6 | AD28: 106.8 | AE28: 109 | AF28: 113.7 | AG28: =SUM($E28:$Q28) -> 1491.7 | AH28: =SUM($S28:$U28) -> 334.5 | AI28: =SUM(W28,Y28,AC28) -> 329.9 | AJ28: =SUM(Z28,AD28) -> 214.9 | AK28: =SUM(X28,AA28) -> 220.4 | AL28: =SUM(AE28,R28,AB28) -> 328.5
A29: Rural | B29: 2013 | C29: October | D29: =B29&" "&C29 -> 2013 October | E29: 116.3 | F29: 115.4 | G29: 112.6 | H29: 111.7 | I29: 107.7 | J29: 113.2 | K29: 164.9 | L29: 108.3 | M29: 103.9 | N29: 108.2 | O29: 111.1 | P29: 114.9 | Q29: 119.8 | R29: 112.2 | S29: 113.6 | T29: 112.3 | U29: 113.4 | V29: NA | W29: =IF(OR(V29="NA",V29="-"),V30,V29) -> 110.5 | X29: 111.6 | Y29: 110.4 | Z29: 108.9 | AA29: 109.3 | AB29: 108.3 | AC29: 110.2 | AD29: 107.5 | AE29: 109.1 | AF29: 115.5 | AG29: =SUM($E29:$Q29) -> 1508 | AH29: =SUM($S29:$U29) -> 339.3 | AI29: =SUM(W29,Y29,AC29) -> 331.1 | AJ29: =SUM(Z29,AD29) -> 216.4 | AK29: =SUM(X29,AA29) -> 220.9 | AL29: =SUM(AE29,R29,AB29) -> 329.6
A30: Urban | B30: 2013 | C30: October | D30: =B30&" "&C30 -> 2013 October | E30: 118.9 | F30: 118.1 | G30: 114.5 | H30: 110.4 | I30: 102.3 | J30: 106.2 | K30: 183.5 | L30: 105.3 | M30: 100.2 | N30: 109.6 | O30: 111.4 | P30: 116 | Q30: 120.8 | R30: 113.5 | S30: 112.5 | T30: 109.7 | U30: 112 | V30: 110.5 | W30: =IF(OR(V30="NA",V30="-"),V31,V30) -> 110.5 | X30: 109.7 | Y30: 110.2 | Z30: 108.2 | AA30: 109.7 | AB30: 108 | AC30: 111.3 | AD30: 107.3 | AE30: 109.4 | AF30: 114 | AG30: =SUM($E30:$Q30) -> 1517.2 | AH30: =SUM($S30:$U30) -> 334.2 | AI30: =SUM(W30,Y30,AC30) -> 332 | AJ30: =SUM(Z30,AD30) -> 215.5 | AK30: =SUM(X30,AA30) -> 219.4 | AL30: =SUM(AE30,R30,AB30) -> 330.9
A31: Rural+Urban | B31: 2013 | C31: October | D31: =B31&" "&C31 -> 2013 October | E31: 117.1 | F31: 116.3 | G31: 113.3 | H31: 111.2 | I31: 105.7 | J31: 109.9 | K31: 171.2 | L31: 107.3 | M31: 102.7 | N31: 108.7 | O31: 111.2 | P31: 115.4 | Q31: 120.2 | R31: 112.5 | S31: 113.2 | T31: 111.2 | U31: 112.8 | V31: 110.5 | W31: =IF(OR(V31="NA",V31="-"),V32,V31) -> 110.5 | X31: 110.9 | Y31: 110.3 | Z31: 108.6 | AA31: 109.5 | AB31: 108.1 | AC31: 110.8 | AD31: 107.4 | AE31: 109.2 | AF31: 114.8 | AG31: =SUM($E31:$Q31) -> 1510.2 | AH31: =SUM($S31:$U31) -> 337.2 | AI31: =SUM(W31,Y31,AC31) -> 331.6 | AJ31: =SUM(Z31,AD31) -> 216 | AK31: =SUM(X31,AA31) -> 220.4 | AL31: =SUM(AE31,R31,AB31) -> 329.8
